Workbook

Sheet Plan1
A1: Dados base | M1: Possiveis Itens | N1: Estatísticas | AI1: Ações | AO1: Perícias
A2: Nome | B2: Anotação | C2: Descricao | D2: Aparencia | E2: Habitat | F2: Curiosidades de Astrolong TerraNova | G2: Categoria | H2: Tipo | I2: Natureza | J2: Grau de Ameaça | K2: Tamanho | L2: Comportamento | M2: Itens | N2: FOR | O2: DES | P2: VIT | Q2: INT | R2: PRE | S2: Pontos de Vida | T2: Pontos de Mana | U2: Defesa | V2: Fortitude | W2: Reflexos | X2: Vontade (Resistência) | Y2: Percepção | Z2: Iniciativa | AA2: Deslocamento | AB2: Sentidos Especiais | AC2: Resistências | AD2: Vulnerabilidades | AE2: Ataque Básico | AF2: CD Conjurador | AG2: Atributo Conjurador | AH2: Tesouro | AI2: Ação Padrão 1 | AJ2: Ação Padrão 2 | AK2: Ação de Movimento | AL2: Reação | AM2: Ação Livre | AN2: Ação Completa | AO2: Atletismo | AP2: Reflexo | AQ2: Tenacidade | AR2: Vontade | AS2: Foco | AT2: Luta | AU2: Sobrevivência
A3: Dríade das Florestas Ancestrais | B3: Poucos aventureiros encontram uma Dríade. Menos ainda percebem que foram observados por uma durante toda a viagem. — Astrolong TerraNova | C3: As Dríades das Florestas Ancestrais são criaturas humanoides compostas por madeira viva, folhas, flores e mana natural. Diferente do que muitos acreditam, elas não são espíritos nem elementais. São seres vivos pertencentes à categoria das Bestas Mágicas e possuem sociedades próprias escondidas nas profundezas das florestas élficas. Suas comunidades raramente ultrapassam algumas dezenas de indivíduos e costumam existir próximas a árvores ancestrais ou fontes naturais de mana. Embora possuam aparência delicada, as Dríades vivem por séculos e acumulam conhecimento profundo sobre a floresta. | D3: Criatura humanide que se assemelha muita a humanos e elfos, com corpos cobertos de vegetação, tem rosto simpaticos e muita belas. | E3: Reino dos Elfos, Florestas Ancestrais | F3: Muitos aventureiros descrevem as Dríades como belas. Isso é verdade. Porém, a beleza não é a característica mais impressionante delas. O que realmente chama atenção é sua capacidade de permanecer completamente imóvel por horas. Mais de uma vez passei por uma árvore para descobrir, dias depois, que ela estava me observando. | G3: Besta Mágica - Tribal | H3: Planta | I3: Arcano, Água e Terra | J3: Comum | K3: Médio | L3: Tribal, Social e Pacificos | M3: Flores de Mana Sementes Feéricas Essência Natural Frutos Ancestrais
A4: Ent Jovem | B4: Quando uma floresta deseja se defender, ela cria espinhos. Quando deseja se lembrar, cria Ents. — Astrolong TerraNova | C4: Os Ents Jovens são árvores despertas pela mana das Florestas Ancestrais. Diferente das Dríades, que possuem comunidades e cultura própria, os Ents existem como guardiões vivos da natureza. Seu corpo é formado por madeira viva extremamente resistente, coberta por musgos, flores, cipós e pequenos animais que frequentemente utilizam sua estrutura como abrigo. Embora sejam chamados de jovens, muitos já possuem mais de cinquenta anos de idade. O termo é utilizado pelos Elfos para diferenciar indivíduos que ainda não atingiram o tamanho colossal dos Ents Ancestrais. São criaturas lentas e pacientes. Um Ent pode permanecer imóvel por semanas observando uma mesma região antes de agir. | D4: Um Ent Jovem possui entre 4 e 6 metros de altura. Seu tronco lembra o de uma árvore centenária, enquanto seus braços assumem a forma de galhos robustos capazes de esmagar pedras. Seu rosto surge naturalmente na madeira, formado por rachaduras e nós que lembram olhos, nariz e boca. Durante a primavera, alguns desenvolvem flores e folhas coloridas em seus ombros e braços. | E4: Reino dos Elfos, Florestas Ancestrais | F4: Muitos aventureiros acreditam que os Ents são lentos porque são árvores. Estão enganados. Eles são lentos porque já viram séculos passarem diante de seus olhos. Para uma criatura que mede o tempo em florestas e não em anos, nós somos os apressados. | G4: Besta Mágica | H4: Planta | I4: Terra | J4: Ameaça | K4: Grande | L4: Territórialista | M4: Madeira Ancestral Seiva Encantada Núcleo de Mana Natural Sementes Primordiais
A5: Ave do Paraíso Ancestral | B5: Durante décadas acreditei que os bardos exageravam ao descrever estas aves. Descobri meu erro no momento em que vi um bando cruzar o céu ao amanhecer. Nenhuma tinta é capaz de reproduzir todas as cores que brilham em suas penas. | C5: A Ave do Paraíso Ancestral é considerada uma das criaturas mais belas de todo o Continente Ancestral. Seu canto harmonioso pode ser ouvido ao amanhecer e ao entardecer, sendo frequentemente associado a presságios de boa sorte por viajantes e habitantes das florestas. Apesar de ser conhecida como uma única espécie, estudiosos catalogaram mais de duzentas variedades diferentes espalhadas pelas florestas, pradarias e bosques do continente. Cada espécie apresenta combinações únicas de cores, padrões e formatos de penas. As Dríades acreditam que essas aves surgiram quando os primeiros ventos da criação atravessaram as florestas recém-nascidas, espalhando fragmentos de mana sobre as árvores ancestrais. São criaturas extremamente importantes para o equilíbrio natural, atuando na dispersão de sementes, pólen mágico e pequenas essências naturais entre diferentes regiões da floresta. | D5: A Ave do Paraíso Ancestral possui entre 20 e 40 centímetros de comprimento, com corpo leve e elegante adaptado ao voo ágil entre galhos e copas densas. Suas penas apresentam uma impressionante variedade de cores vibrantes, incluindo tons de azul, verde-esmeralda, dourado, violeta, vermelho-rubi e branco-perolado. Algumas espécies possuem caudas longas que podem atingir três vezes o comprimento do corpo. Quando expostas à luz do sol ou à mana ambiente, certas penas produzem reflexos iridescentes que mudam constantemente de cor, criando um espetáculo visual difícil de descrever. Os machos geralmente apresentam plumagens mais extravagantes, enquanto as fêmeas possuem padrões mais discretos, porém igualmente belos. Diversas espécies desenvolvem pequenas cristas, leques de penas ou caudas ornamentais utilizadas durante elaborados rituais de acasalamento que transformam clareiras inteiras em verdadeiros espetáculos naturais. | E5: Reino dos Elfos, Terras dos Faunos e Florestas Ancestrais | F5: A maioria dos aventureiros observa apenas a plumagem dessas aves. Eu prefiro observar os outros animais ao seu redor. Em mais de uma ocasião, encontrei predadores descansando próximos a um bando de Aves do Paraíso Ancestrais sem demonstrar qualquer intenção de caça. Não compreendo completamente o motivo, mas suspeito que a mana presente em suas penas produza uma sensação de tranquilidade nas criaturas ao redor. | G5: Besta Mágica | H5: Ave | I5: Vento | J5: Inofensivo | K5: Pequeno | L5: Pacífico e Sociável | M5: Pena Arcoiris
A6: MegaMutty | B6: Quando vi um pela primeira vez à distância, pensei estar observando uma colina ambulante. Somente após me aproximar percebi que se tratava de uma criatura viva. O mais curioso foi descobrir que a enorme besta que poderia facilmente me esmagar estava mais interessada em comer frutas do que em me atacar. — Astrolong TerraNova | C6: Os MegaMuttys são grandes mamíferos mágicos conhecidos por sua natureza dócil e comportamento altamente social. Vivem em pequenos grupos familiares que podem variar entre seis e vinte indivíduos, percorrendo extensas áreas de floresta e pradarias em busca de alimento. Apesar de sua aparência intimidadora e enorme força física, raramente demonstram agressividade contra outras criaturas. A maioria dos conflitos envolvendo MegaMuttys ocorre durante a estação de acasalamento ou quando um filhote é ameaçado. São considerados uma das espécies mais importantes da região, pois ajudam a moldar o ambiente por onde passam. Ao derrubarem árvores antigas, abrirem trilhas naturais e espalharem sementes durante suas migrações, contribuem diretamente para a renovação das florestas. Muitos Faunos os consideram símbolos de prosperidade, enquanto alguns Elfos os enxergam como guardiões silenciosos das fronteiras naturais entre os bosques e as pradarias. | D6: Um MegaMutty adulto possui entre três e quatro metros de altura quando apoiado sobre as quatro patas e pode ultrapassar oito metros de comprimento. Seu corpo é robusto e extremamente musculoso, sustentado por patas grossas adaptadas para longas caminhadas e investidas devastadoras. Sua anatomia lembra a de um enorme mamífero quadrúpede coberto por uma espessa camada de pelos marrons, cinzentos e negros que o protege das mudanças climáticas. A cabeça apresenta um focinho alongado e poderoso, enquanto suas presas curvas crescem para frente, sendo utilizadas para escavar raízes, derrubar árvores e disputar parceiros durante a época reprodutiva. Os indivíduos mais velhos costumam desenvolver camadas ainda mais densas de pelos, frequentemente cobertas por musgos, flores e pequenos insetos que passam a viver em simbiose com a criatura. | E6: Fronteiras entre o Reino dos Elfos e as Terras dos Faunos | F6: A maioria dos aventureiros acredita que os MegaMuttys são perigosos por causa do tamanho. Na realidade, são perigosos por causa da velocidade. Poucos esperam que uma criatura tão grande consiga atravessar uma clareira inteira em poucos segundos. Os filhotes permanecem próximos da mãe por quase cinco anos. Durante esse período, qualquer criatura que se aproxime demais será tratada como uma ameaça, independentemente de suas intenções. Em uma ocasião observei um grupo de Dríades utilizando um MegaMutty adormecido como ponto de encontro. A criatura sequer pareceu se importar quando acordou cercada por elas. As trilhas abertas pelos rebanhos mais antigos são tão utilizadas por outras criaturas que alguns mapas élficos as registram como rotas permanentes de viagem. Jamais confunda um MegaMutty relaxado com um MegaMutty amigável. Eles são pacíficos, mas continuam sendo criaturas capazes de derrubar uma árvore centenária com uma única investida. | G6: Besta Mágica | H6: Besta | I6: Terra | J6: Comum | K6: Grande | L6: Social e Pacífico (Territorial durante o acasalamento e proteção dos filhotes) | M6: Presas de MegaMutty Couro Espesso de MegaMutty Pelagem Gigante Osso Reforçado Glândula de Resistência Natural Musgos Simbióticos Crescidos na Pelagem Fragmentos de Mana Natural
A7: Pantera Felina Negra | B7: A maioria dos viajantes acredita que a escuridão da Floresta Negra esconde monstros. Estão parcialmente corretos. O verdadeiro problema é que algumas criaturas se tornaram tão adaptadas à escuridão que a própria floresta parece conspirar para ocultá-las. Nenhuma representa melhor isso do que a Pantera Felina Negra. — Astrolong TerraNova | C7: A Pantera Felina Negra é uma das cinco espécies conhecidas de Panteras Felinas. Embora compartilhem a característica comum de possuir dois pares de pernas dianteiras e um par de pernas traseiras, esta espécie se destaca por sua extraordinária adaptação à vida noturna. Habitando as regiões mais profundas da Floresta Negra, esses predadores raramente são vistos durante o dia. Preferem caçar sob a cobertura da noite, utilizando a vegetação densa e as sombras naturais para se aproximarem de suas presas sem serem percebidos. Sua dieta é composta principalmente por cervos, javalis, pequenos monstros da floresta e, ocasionalmente, criaturas mágicas menores. Ataques contra humanoides são raros e geralmente ocorrem apenas quando o animal se sente encurralado ou quando seu território é invadido repetidamente. Apesar da reputação assustadora, a Pantera Felina Negra desempenha um papel fundamental no equilíbrio ecológico da Floresta Negra, controlando populações de criaturas menores e eliminando indivíduos doentes ou enfraquecidos. | D7: Uma Pantera Felina Negra adulta possui aproximadamente 300 quilos de massa corporal e pode atingir mais de quatro metros de comprimento da cabeça até a ponta da cauda. Seu corpo musculoso é sustentado por seis patas poderosas: quatro dianteiras e duas traseiras. Essa anatomia incomum proporciona estabilidade excepcional durante corridas, saltos e emboscadas. Toda sua pelagem é composta por pelos negros extremamente densos, capazes de absorver grande parte da luz ambiente. Sob certas condições, a criatura parece se fundir completamente às sombras da floresta. Seus olhos brilham em tons de verde-esmeralda ou dourado intenso durante a noite, sendo muitas vezes a única parte visível do animal quando está observando uma presa. A cauda longa auxilia no equilíbrio durante perseguições e saltos entre raízes, rochas e troncos caídos. | E7: Floresta Negra | F7: Em vinte e três anos explorando a Floresta Negra, encontrei rastros de Panteras Felinas Negras centenas de vezes. Vi uma delas apenas quatro. Seu corpo produz tão pouco ruído durante a movimentação que alguns caçadores acreditam que a criatura utiliza magia para silenciar seus passos. Até o momento não encontrei evidências que comprovem essa teoria. Os filhotes nascem com manchas cinzentas espalhadas pela pelagem. Essas marcas desaparecem completamente antes de atingirem a idade adulta. É comum encontrar cervos e outras presas vivendo relativamente próximos do território de uma Pantera Felina Negra. Diferente de muitos predadores, elas raramente matam mais do que o necessário para se alimentar. A primeira vez que percebi estar sendo seguido por uma dessas criaturas foi ao notar que os pássaros haviam parado de cantar. A segunda vez, percebi tarde demais. | G7: Besta Mágica | H7: Felina | I7: Terra e Vento | J7: Ameaça | K7: Grande | L7: Solitário, Territorial e Predador Noturno | M7: Presas de Pantera Negra Garras Sombrias Couro Negro Reforçado Pelagem Noturna Olhos Cristalizados de Pantera Bigodes Sensoriais Glândula de Caça Noturna Essência Predatória
A8: Pantera Felina Marrom | B8: Diferente de sua prima da Floresta Negra, a Pantera Felina Marrom não se esconde nas sombras. Ela prefere observar o mundo sob a luz do sol, descansando sobre rochedos elevados ou galhos robustos enquanto vigia seu território. Muitos viajantes sequer percebem que estão sendo observados até que a criatura decida partir. — Astrolong TerraNova | C8: A Pantera Felina Marrom é uma das espécies mais comuns entre os grandes felinos de seis patas encontrados no Continente Ancestral. Habita principalmente encostas montanhosas, florestas elevadas e regiões de transição entre os bosques élficos e as montanhas anãs. Embora seja um predador eficiente, raramente demonstra agressividade gratuita. Sua estratégia de caça baseia-se em paciência, observação e emboscadas rápidas, utilizando a vegetação e os desníveis do terreno para se aproximar das presas. Sua dieta é composta principalmente por cervos, cabras-montesas, javalis, aves de grande porte e outras criaturas de médio porte. Em regiões montanhosas, são frequentemente vistas caçando ao longo de penhascos e trilhas estreitas. Anões costumam respeitar essas criaturas, considerando-as símbolos de força e independência. Já os Elfos as enxergam como importantes guardiãs naturais das fronteiras selvagens. | D8: Uma Pantera Felina Marrom adulta pesa aproximadamente 150 quilos e mede entre três e quatro metros de comprimento. Seu corpo apresenta a característica típica das Panteras Felinas: dois pares de patas dianteiras e um par de patas traseiras. Essa anatomia proporciona equilíbrio excepcional durante escaladas, perseguições e saltos entre rochas. A pelagem varia entre diferentes tons de marrom, castanho, cobre e bege, permitindo excelente camuflagem em montanhas, bosques secos e regiões rochosas. Sua musculatura é mais compacta e ágil que a da Pantera Felina Negra, sendo adaptada para terrenos acidentados. A longa cauda auxilia no equilíbrio durante deslocamentos sobre penhascos e galhos elevados. Os olhos costumam apresentar coloração âmbar, dourada ou cobre, refletindo intensamente a luz solar. As quatro patas dianteiras terminam em garras retráteis extremamente afiadas, capazes de se fixar em superfícies rochosas quase verticais. | E8: Reino dos Anões e Reino dos Elfos | F8: Se uma Pantera Felina Negra é um fantasma da noite, a Pantera Felina Marrom é uma rainha das montanhas. Durante minhas expedições ao Reino dos Anões observei diversas vezes indivíduos descansando sobre formações rochosas tão altas que pareciam impossíveis de alcançar. Ainda hoje não compreendo completamente como conseguem subir até alguns daqueles locais. Filhotes costumam brincar simulando caçadas entre si. Curiosamente, utilizam as quatro patas dianteiras para imobilizar os irmãos enquanto praticam mordidas controladas. Muitos caçadores acreditam que a espécie possui um senso de direção sobrenatural. Diversos indivíduos marcados por estudiosos foram observados retornando exatamente ao mesmo território anos depois. Embora sejam predadores temidos, são conhecidos por evitar confrontos desnecessários. Em mais de uma ocasião observei uma Pantera Felina Marrom abandonar uma caça ao perceber a presença de filhotes de outra espécie nas proximidades. | G8: Besta Mágica | H8: Felina | I8: Terra | J8: Menor | K8: Grande | L8: Solitário, Territorial e Predador Diurno | M8: Garras de Pantera Marrom Presas Serrilhadas Couro Montanhês Pelagem Castanha Bigodes Sensoriais Olhos Âmbar Cristalizados Glândula de Equilíbrio Essência de Predador Alpino
A9: Pantera Felina Real | B9: Entre todas as Panteras Felinas que cataloguei, nenhuma demonstra tanta nobreza quanto a Pantera Felina Real. Elas caminham pelas pradarias e florestas como verdadeiros reis da natureza. Curiosamente, já encontrei indivíduos que toleraram minha presença por dias inteiros, observando-me com a mesma curiosidade que eu observava a eles. — Astrolong TerraNova | C9: A Pantera Felina Real é considerada a mais majestosa das cinco espécies conhecidas de Panteras Felinas. Diferente de suas parentes mais solitárias, vivem em grupos familiares organizados chamados de bandos reais. Esses grupos normalmente são liderados por um macho dominante, acompanhado por diversas fêmeas adultas, filhotes e jovens em treinamento. São criaturas naturalmente pacíficas e costumam ignorar viajantes, aventureiros e até outras espécies, desde que não representem ameaça ao grupo. Durante a época de reprodução, entretanto, seu comportamento muda drasticamente. Machos disputam território e direito de acasalamento através de confrontos violentos que podem durar horas. Nesse período tornam-se extremamente agressivos e perigosos. As fêmeas também demonstram feroz instinto protetor quando possuem filhotes recém-nascidos, atacando imediatamente qualquer criatura que se aproxime demais. Apesar disso, fora dessas situações, são consideradas uma das grandes maravilhas vivas do Continente Ancestral. | D9: Uma Pantera Felina Real adulta pode atingir cerca de 450 quilos e ultrapassar cinco metros de comprimento da cabeça até a ponta da cauda. Como todas as Panteras Felinas, possui dois pares de patas dianteiras e um único par de patas traseiras, característica que lhe proporciona estabilidade extraordinária durante corridas, saltos e combates. Sua pelagem varia entre tons dourados, laranja intenso e cobre brilhante. Sob a luz do sol, seus pelos parecem refletir a própria luz, produzindo um brilho majestoso visível a grandes distâncias. Os machos desenvolvem uma exuberante juba dourada que cresce ao redor do pescoço, peito e ombros. Quanto mais velho e dominante o indivíduo, maior tende a ser sua juba. Seus olhos costumam apresentar coloração âmbar, dourada ou alaranjada, transmitindo uma expressão de inteligência, confiança e serenidade. Sua musculatura é impressionante, combinando força bruta com elegância e agilidade raramente vistas em criaturas de seu porte. | E9: Terras dos Faunos e Reino dos Elfos | F9: Já observei grupos de Faunos caminhando ao lado de Panteras Felinas Reais sem qualquer demonstração de medo. Nenhuma das partes parecia considerar a outra uma ameaça. Filhotes são criados coletivamente por todas as fêmeas do grupo. Em alguns casos, uma única ninhada pode receber cuidados de cinco ou seis mães diferentes. Os rugidos dos machos podem ser ouvidos a quilômetros de distância durante a estação de reprodução. O som ecoa pelas pradarias como um trovão distante. Ao contrário do que muitos acreditam, a juba não serve apenas para impressionar parceiros. Ela também protege regiões vitais do pescoço durante disputas territoriais. Entre os Faunos existe a crença de que encontrar uma Pantera Felina Real descansando tranquilamente durante uma viagem é um presságio de boa sorte e prosperidade. | G9: Besta Mágica | H9: Felina | I9: Terra e Trovão | J9: Ameaça | K9: Grande | L9: Social, Familiar e Territorial durante reprodução ou proteção dos filhotes | M9: Juba Dourada de Pantera Real Garras Reais Presas Majestosas Couro Real Olhos Âmbar Cristalizados Bigodes Sensoriais Glândula de Vitalidade Essência do Guardião da Pradaria
A10: Pantera Felina dos Riachos Albina | B10: Poucas criaturas conseguem transmitir beleza e perigo na mesma medida. A Pantera dos Riachos Albina parece uma escultura viva de gelo e neve quando observada à distância. Muitos exploradores ficam fascinados por sua aparência majestosa. Os mais imprudentes raramente têm uma segunda oportunidade para admirar sua beleza. — Astrolong TerraNova | C10: A Pantera Felina dos Riachos Albina é uma variante rara das Panteras Felinas adaptada às regiões geladas do extremo norte. Considerada uma das mais eficientes predadoras do Continente Ancestral, desenvolveu habilidades extraordinárias para caça tanto em terra quanto na água. Embora possa perseguir presas sobre a neve, escalar encostas e atravessar terrenos congelados com facilidade, seu verdadeiro domínio encontra-se nos rios, lagos e canais subterrâneos das Terras do Norte Gelado. Essas criaturas são capazes de permanecer submersas por longos períodos, utilizando sua excepcional capacidade pulmonar e controle corporal para se aproximar silenciosamente das presas. Peixes gigantes, focas glaciais, cervos do norte e até jovens gigantes podem se tornar alvos de uma Pantera dos Riachos adulta. Apesar de serem predadoras extremamente eficientes, raramente desperdiçam energia em conflitos desnecessários. | D10: Uma Pantera Felina dos Riachos Albina adulta pode ultrapassar os 250 quilos e atingir mais de quatro metros de comprimento. Seu corpo possui a anatomia característica das Panteras Felinas, com dois pares de patas dianteiras e um único par de patas traseiras. Sua pelagem é completamente branca, variando entre tons de neve, marfim e prata clara. Em alguns indivíduos, manchas extremamente sutis podem ser observadas sob determinadas condições de iluminação. Os olhos costumam apresentar coloração azul-glacial, violeta pálido ou vermelho-rubi, características comuns do albinismo presente na espécie. Sua musculatura é compacta e poderosa, especialmente na região dos ombros e das patas dianteiras, permitindo explosões repentinas de velocidade tanto na água quanto em terra firme. As patas possuem membranas discretas entre os dedos que aumentam significativamente sua eficiência durante a natação. Observação Anatômica As patas dianteiras menores possuem articulações especiais que permitem recolher completamente as garras e dobrar parte da estrutura óssea atrás do par principal de patas dianteiras. Essa adaptação faz com que muitos observadores acreditem estar diante de uma criatura de quatro patas até o momento do ataque. Quando necessário, essas patas ocultas são utilizadas para desferir golpes inesperados, agarrar presas ou aumentar drasticamente sua capacidade de escalada e natação. | E10: Terras do Norte Gelado, rios congelados, lagos glaciais, vales nevados e encostas montanhosas | F10: Já observei uma Pantera dos Riachos permanecer imóvel sob uma camada de gelo por quase uma hora inteira aguardando o momento ideal para atacar. Os habitantes das Terras Geladas costumam chamá-las de Fantasmas Brancos dos Rios, pois muitas vezes a única coisa visível é o reflexo de seus olhos sob a água. Durante uma expedição, testemunhei uma dessas criaturas capturar um peixe quase do mesmo tamanho que seu próprio corpo. A luta durou menos de trinta segundos. Poucos aventureiros sabem da existência de suas patas ocultas. Mais de um caçador experiente foi surpreendido ao descobrir que a criatura possuía muito mais alcance e controle do que aparentava. Embora sejam predadoras formidáveis, as mães demonstram cuidado extraordinário com seus filhotes. Já vi uma delas atravessar um rio parcialmente congelado diversas vezes para transportar seus jovens em segurança. Entre os povos do norte existe uma antiga crença de que avistar uma Pantera dos Riachos Albina nadando contra a corrente significa que uma grande mudança está prestes a acontecer. | G10: Besta Mágica | H10: Felina | I10: Terra e Água | J10: Elite | K10: Grande | L10: Solitária ou Familiar, Territorial, Predadora Aquática | M10: Pelagem Glacial Albina Garras Ocultas dos Riachos Presas do Caçador Ártico Couro Impermeável Superior Bigodes Sensoriais Aquáticos Olhos Cristalinos Glaciais Membranas Natatórias Glândula de Respiração Prolongada Essência da Caçadora dos Rios Gelados
A11: Pantera Felina das Areias | B11: Se a Pantera Felina Negra é a sombra e a Pantera Felina dos Riachos é a água, então a Pantera Felina das Areias é o próprio vento. Já observei uma delas desaparecer no horizonte mais rápido do que um cavalo em disparada. Felizmente para os aventureiros, elas preferem fugir de problemas em vez de procurá-los. — Astrolong TerraNova | C11: A Pantera Felina das Areias é considerada a mais veloz entre todas as espécies conhecidas de Panteras Felinas. Adaptada aos terrenos áridos, pradarias secas e regiões de vegetação escassa das Terras Devastadas, desenvolveu um corpo extremamente leve e eficiente. Diferente de suas parentes maiores e mais agressivas, esta espécie evita conflitos sempre que possível. Seu primeiro instinto diante de qualquer ameaça é a fuga, utilizando sua velocidade extraordinária para escapar antes mesmo que um confronto aconteça. Sua dieta é composta principalmente por pequenos mamíferos, répteis, aves terrestres e criaturas de médio porte. Apesar de ser uma caçadora eficiente, raramente enfrenta presas muito maiores que ela. Durante a época de reprodução, entretanto, seu comportamento muda drasticamente. Machos tornam-se extremamente competitivos e disputam territórios através de corridas, demonstrações de velocidade e confrontos rápidos, porém violentos. Por sua natureza cautelosa, muitos estudiosos acreditam que existam mais Panteras das Areias do que os registros indicam, já que poucas pessoas conseguem observá-las por tempo suficiente para estudá-las adequadamente. | D11: Uma Pantera Felina das Areias adulta pesa cerca de 100 quilos, embora indivíduos excepcionais possam ultrapassar os 120 quilos. Seu corpo apresenta a anatomia característica das Panteras Felinas, com dois pares de patas dianteiras e um par de patas traseiras. Entre todas as espécies, possui a estrutura corporal mais esguia e aerodinâmica. A pelagem combina tons de amarelo dourado, laranja queimado, vermelho-terra e manchas escuras espalhadas pelo corpo. Sua musculatura é seca e alongada, construída para velocidade em vez de força bruta. As pernas longas permitem passadas impressionantes, enquanto a cauda comprida atua como leme durante curvas realizadas em alta velocidade. Os olhos geralmente apresentam coloração âmbar, dourada ou cobre intenso, adaptados para detectar movimentos a grandes distâncias. Em disparada máxima, uma Pantera Felina das Areias pode ultrapassar os 120 quilômetros por hora durante curtas distâncias, tornando-a uma das criaturas terrestres mais rápidas já catalogadas por Astrolong TerraNova. | E11: Terras Devastadas, fronteiras da Floresta dos Orcs, arredores da Floresta Negra e ocasionalmente as Terras dos Gigantes | F11: A maioria dos predadores foge quando está ferida. A Pantera das Areias foge quando está saudável. Já acompanhei um indivíduo por quase três dias antes que ele finalmente permitisse que eu me aproximasse o suficiente para observá-lo adequadamente. Os filhotes passam boa parte da infância disputando corridas entre si. A velocidade parece ser tão importante para sua sociedade quanto a força é para outras espécies. Durante uma tempestade de areia, observei uma dessas criaturas utilizar as próprias dunas como cobertura, movendo-se de forma tão eficiente que parecia desaparecer entre os grãos de areia. Embora possam alcançar velocidades impressionantes, raramente mantêm uma perseguição longa. Seu método de caça consiste em explosões repentinas de velocidade seguidas de ataques extremamente precisos. Entre os Orcs existe a crença de que capturar uma Pantera das Areias é impossível. Após muitos anos estudando a espécie, acredito que talvez estejam certos. | G11: Besta Mágica | H11: Felina | I11: Terra e Vento | J11: Ameaça | K11: Elite | L11: Arisco, Medroso, Territorial durante o período reprodutivo | M11: Couro das Areias Garras de Velocidade Presas Serrilhadas Bigodes Sensoriais Tendões Elásticos Olhos de Caçador do Deserto Essência da Rapidez Pelagem Escarlate
A12: Urso de Pijama Listrado | B12: A primeira vez que encontrei um Urso de Pijama Listrado, pensei estar observando uma criatura lenta e pesada descansando à margem de um lago. Instantes depois, vi a besta atravessar dezenas de metros de água em poucos segundos e arrancar um Peixe Gigante Vermelho do rio com uma única investida. Nunca mais subestimei sua velocidade. — Astrolong TerraNova | C12: O Urso de Pijama Listrado é uma das maiores bestas terrestres conhecidas do mundo. Habitando regiões frias e montanhosas próximas às Terras dos Gigantes e às Ilhas dos Dragões, tornou-se um dos predadores mais respeitados desses territórios. Apesar de seu tamanho colossal, raramente entra em conflito com outras criaturas. Prefere patrulhar sozinho vastas extensões de território, visitando regularmente rios e lagos onde caça sua presa favorita: os Peixes Gigantes Vermelhos. Sua técnica de caça é simples, mas devastadora. Permanecendo imóvel próximo à água, aguarda pacientemente o momento exato para atacar. Quando a presa se aproxima, avança com velocidade surpreendente, utilizando seus enormes membros dianteiros para capturá-la. Uma vez agarrada, escapar torna-se praticamente impossível. O abraço do Urso de Pijama Listrado é conhecido entre os caçadores como o Abraço do Penhasco, pois poucos seres possuem força suficiente para romper sua imobilização. | D12: O Urso de Pijama Listrado pode ultrapassar os 800 quilos e atingir mais de quatro metros de altura quando se ergue sobre as patas traseiras. Seu corpo é coberto por uma espessa pelagem listrada composta por faixas negras, cinzentas, castanhas e douradas. Os padrões são únicos para cada indivíduo e lembram as sombras projetadas pelas montanhas ao amanhecer. Sua anatomia é extremamente incomum. As patas dianteiras são significativamente maiores que as traseiras, formando ombros largos e musculosos capazes de mover pedras e derrubar árvores jovens. As garras dianteiras podem atingir quase meio metro de comprimento em indivíduos mais velhos, sendo utilizadas tanto para escavar quanto para capturar presas. Quando ataca, o Urso utiliza os braços para envolver completamente o alvo. Nesse momento, suas patas traseiras entram em ação, prendendo a vítima contra seu corpo enquanto as enormes garras impedem qualquer tentativa de fuga. A combinação entre força, peso e alcance faz com que poucas criaturas consigam escapar após serem capturadas. Sua cabeça apresenta focinho largo, mandíbulas poderosas e olhos pequenos, porém extremamente atentos. | E12: Terras dos Gigantes, Ilhas dos Dragões, costas geladas, grandes rios, lagos profundos e regiões montanhosas próximas ao mar | F12: Apesar de sua aparência feroz, os Urso de Pijama Listrado passam boa parte do dia descansando próximo a rios e lagos. Já encontrei indivíduos observando cardumes por horas antes de realizar um único ataque. Sua paciência rivaliza com a dos melhores caçadores. Muitos aventureiros acreditam que suas patas dianteiras servem apenas para combate. Na verdade, são ferramentas incrivelmente versáteis, utilizadas para escavar, nadar, escalar e até mover obstáculos enormes. Os Gigantes costumam respeitar essas criaturas. Em algumas regiões, matar um Urso de Pijama Listrado sem necessidade é considerado um ato de extrema desonra. Poucas criaturas conseguem enfrentar um adulto saudável. Mesmo dragões jovens evitam conflitos desnecessários com eles. Durante minhas viagens, encontrei marcas de garras gravadas em rochas sólidas por indivíduos que provavelmente viveram há séculos. | G12: Besta Mágica | H12: Besta | I12: Terra | J12: Elite | K12: Enorme | L12: Solitário, Territorial e Predador de Emboscada | M12: Tesouros Pelagem Listrada Gigante Garras do Abraço Implacável Presas Quebra-Ossos Couro Reforçado de Montanha Ossos de Predador Colossal Óleo de Glândulas Naturais Coração de Caçador Solitário Essência da Força Selvagem
A13: Urso-Baleia Branco | B13: Nenhuma criatura me ensinou mais sobre aparências enganosas do que o Urso-Baleia Branco. Seu rosto transmite uma expressão quase amigável, como se estivesse constantemente satisfeito com a vida. Infelizmente, ele também considera quase tudo que encontra uma possível refeição. — Astrolong TerraNova | C13: O Urso-Baleia Branco é o maior entre todas as espécies de ursos conhecidas do mundo. Habitando regiões geladas onde terra, gelo e oceano se encontram, tornou-se o predador dominante de inúmeras costas congeladas. Diferente de outros grandes predadores que dependem de velocidade ou emboscadas elaboradas, o Urso-Baleia Branco utiliza uma estratégia que muitos aventureiros descrevem como perturbadora. Ele simplesmente se aproxima. Sem demonstrar pressa, sem rugidos e sem qualquer sinal de agressividade aparente, a criatura avança lentamente em direção ao alvo. Muitos viajantes inexperientes interpretam esse comportamento como curiosidade ou desinteresse. Quando a distância se torna pequena o suficiente, o ataque acontece. Sua explosão repentina de velocidade é tão inesperada que poucas criaturas conseguem reagir a tempo. Embora seja perfeitamente capaz de viver em terra firme, passa grande parte da vida no oceano, onde caça peixes gigantes, focas glaciais, monstros marinhos e praticamente qualquer criatura que considere vulnerável. No mar, poucos predadores rivalizam com sua eficiência. | D13: Um Urso-Baleia Branco adulto pode ultrapassar duas toneladas de peso e atingir mais de cinco metros de comprimento. Seu corpo combina características adaptadas tanto para ambientes terrestres quanto aquáticos. A estrutura é massiva, com musculatura densa escondida sob uma camada espessa de gordura isolante. Sua pelagem é predominantemente branca, porém marcada por grandes manchas negras ou cinza-escuras distribuídas pelo dorso, laterais e cabeça. A cabeça é arredondada e larga, com olhos pequenos e expressivos que frequentemente produzem uma aparência curiosamente amigável. O formato natural de sua mandíbula cria uma impressão constante de sorriso, característica responsável por inúmeros acidentes envolvendo exploradores que subestimaram a criatura. As patas são largas e poderosas, adaptadas para caminhar sobre neve profunda, gelo instável e também para impulsionar o animal durante a natação. Debaixo d'água sua coloração branca e negra se mistura aos reflexos do gelo e às sombras profundas dos mares glaciais, tornando-o surpreendentemente difícil de detectar. Quando observado do fundo para a superfície, muitas vezes parece apenas mais uma formação de gelo flutuante. Até que se mova. | E13: Terras do Norte Gelado, Terras dos Gigantes, mares glaciais, fiordes congelados e costas árticas | F13: Se existe uma criatura capaz de parecer feliz enquanto planeja devorá-lo, é o Urso-Baleia Branco. Já testemunhei um indivíduo nadando sob uma camada de gelo tão espessa que eu sequer percebi sua presença até vê-lo emergir poucos metros adiante. A maioria dos ataques ocorre porque as vítimas acreditam que a criatura está apenas passando. Na realidade, ela já tomou sua decisão há muito tempo. Filhotes são surpreendentemente brincalhões e passam horas deslizando sobre encostas congeladas. Essa diversão frequentemente termina com alguma criatura menor sendo acidentalmente esmagada. Os Gigantes do Norte respeitam profundamente essas criaturas e costumam evitar caçá-las, exceto em situações extremas. Ao contrário da maioria dos predadores, eles não parecem sentir necessidade de demonstrar dominância. Simplesmente agem como se já fossem os donos do território. Em águas profundas, sua silhueta desaparece quase completamente. Mais de um marinheiro jurou que o mar simplesmente abriu uma boca e engoliu sua embarcação. | G13: Besta Mágica | H13: Besta | I13: Terra e Água | J13: Elite | K13: Enorme | L13: Territorial, Agressivo e Predador Semimarinho | M13: Pelagem Glacial Colossal Dentes de Quebra-Gelo Garras Oceânicas Couro Marinho Reforçado Gordura Alquímica Glacial Óleo de Respiração Profunda Ossos de Titã Polar Coração do Predador dos Mares Gelados Essência da Maré Congelante
A14: Urso Anão Marrom | B14: Entre todos os ursos que cataloguei, este é certamente o mais preguiçoso. Já encontrei um indivíduo dormindo no mesmo tronco durante três dias consecutivos. No quarto dia, ele apenas mudou de lado e continuou dormindo. — Astrolong TerraNova | C14: O Urso Anão Marrom é a menor espécie conhecida entre os ursos do mundo, embora seu conceito de pequeno ainda seja consideravelmente maior que o de muitas outras criaturas. Extremamente dóceis quando bem tratados, tornaram-se uma das poucas Bestas Mágicas que podem conviver pacificamente com povos civilizados. Em algumas regiões do Continente Ancestral, especialmente entre Faunos e comunidades élficas mais isoladas, é comum encontrar indivíduos criados desde filhotes como companheiros e animais de guarda. Apesar de sua aparência amigável, continuam sendo criaturas fortes e resistentes. Quando ameaçados, podem utilizar sua poderosa musculatura para afastar predadores ou proteger seus cuidadores. Sua rotina diária consiste principalmente em comer, descansar e procurar novos locais confortáveis para dormir. Muitos indivíduos passam mais da metade da vida descansando. | D14: Um Urso Anão Marrom adulto pesa aproximadamente 200 quilos e possui altura semelhante à de um humanoide adulto quando apoiado sobre as quatro patas. Seu corpo é compacto e robusto, coberto por uma espessa pelagem marrom que varia entre tons castanhos claros e escuros. Possui patas largas adaptadas para caminhar por florestas densas, troncos caídos e terrenos irregulares. Sua cabeça é arredondada, com orelhas pequenas, focinho curto e olhos expressivos que frequentemente transmitem uma aparência tranquila e curiosa. Diferente das demais espécies de ursos, sua constituição corporal favorece conforto e resistência ao invés de velocidade ou agressividade. É comum encontrar folhas, flores e pequenos galhos presos à sua pelagem após longos períodos de sono em clareiras ou bosques. Quando descansando, costuma enrolar-se como uma enorme bola de pelos, tornando difícil distinguir a criatura de um monte de folhas secas à distância. | E14: Pacífico, Sonolento e Sociável | F14: Se a preguiça fosse uma forma de magia, os Ursos Anões Marrons seriam arquimagos. Muitos aventureiros confundem indivíduos adormecidos com pedras cobertas por musgo. Alguns aprendem o erro da maneira mais constrangedora possível quando a 'pedra' começa a roncar. Os filhotes desenvolvem forte apego a criaturas que os alimentam regularmente. Já conheci um que seguiu um ferreiro anão por quase dois meses inteiros. Apesar de sua natureza tranquila, jamais tente acordar um Urso Anão Marrom tocando seu alimento. Alguns instintos permanecem fortes independentemente da personalidade da criatura. As Dríades gostam particularmente da companhia desses animais. Dizem que seu ronco ajuda as árvores jovens a crescerem mais saudáveis. Até hoje não encontrei evidências que comprovem essa teoria. Uma vez observei um indivíduo dormir durante uma tempestade inteira. A chuva parou antes que ele acordasse. | G14: Besta Mágica | H14: Besta | I14: Terra | J14: Comum | K14: Médio | L14: Reino dos Elfos, Terras dos Faunos e florestas temperadas do Continente Ancestral | M14: Tesouros Pelagem Marrom Macia Garras de Escavação Couro Flexível Almofadas Plantares Resistentes Presas de Urso Anão Mel Selvagem Armazenado na Pelagem Essência da Tranquilidade Coração de Guardião da Floresta
... A66: Salamandra das Chamas | B66: "Pequena, adorável e quente o suficiente para transformar uma fogueira em algo desnecessário. A Salamandra das Chamas é uma das poucas criaturas elementais que consegue conquistar o coração de aventureiros sem tentar devorá-los primeiro." — Astrolong TerraNova | C66: As Salamandras das Chamas são pequenos espíritos elementais ligados ao fogo natural do mundo. Apesar de sua origem mágica, raramente representam perigo para outras criaturas. São conhecidas por sua personalidade curiosa e comportamento amigável, aproximando-se frequentemente de acampamentos, forjas e lareiras para observar atividades mortais. Alimentam-se de calor, brasas, energia elemental e pequenas quantidades de mana de fogo presentes no ambiente. Quando felizes, produzem pequenas faíscas que dançam ao seu redor. Embora sejam dóceis, podem tornar-se defensivas caso sejam capturadas ou maltratadas. | D66: Uma Salamandra das Chamas mede entre quinze e trinta centímetros de comprimento. Seu corpo lembra um pequeno anfíbio de formas arredondadas, com grandes olhos brilhantes e expressão constantemente curiosa. Sua pele varia entre vermelho, laranja, dourado e amarelo intenso, emitindo um brilho suave semelhante ao de brasas vivas. Pequenas chamas dançam sobre sua cabeça, costas e cauda sem consumir seu corpo. Quando animadas, essas chamas aumentam de intensidade; quando assustadas, diminuem até parecer apenas carvão incandescente. | E66: Regiões vulcânicas, cavernas aquecidas por magma, fontes termais, montanhas dracônicas e florestas próximas a áreas de atividade geotérmica. | F66: Salamandras das Chamas costumam dormir dentro de fogueiras apagadas. Filhotes de dragões frequentemente tentam brincar com elas. Ferreiros consideram sua presença um sinal de boa sorte para a produção de armas e armaduras. Algumas conseguem aquecer pequenas áreas durante tempestades de neve. É comum vê-las reunidas próximas a rios de lava como se estivessem tomando banho de sol. Apesar de serem espíritos do fogo, não gostam de incêndios descontrolados. Druidas acreditam que elas ajudam a manter o equilíbrio entre destruição e renovação causados pelo elemento fogo. Existem relatos de Salamandras extremamente antigas que se transformaram em poderosos espíritos elementais maiores. | G66: Anfíbio Mágico | H66: Anfibio | I66: Fogo | J66: Comum | K66: Muito Pequeno | L66: Curioso, Brincalhão e Social | M66: Essência de Chama Menor Escama Incandescente Núcleo de Brasa Viva Cristal de Fogo Natural Lágrima Flamejante Cinzas Encantadas Fragmento de Mana Ígnea Coração de Brasa

Sheet Nivels
D3: Grau de Ameaça
C4: =COUNTIF(Plan1!J:J,D4) | D4: Inofensivo | E4: Grau 0 — Inofensivo Criaturas dóceis que raramente apresentam qualquer risco para humanoides. Normalmente fogem diante de ameaças e não possuem capacidade real de causar ferimentos graves, mesmo quando acuadas. Podem servir como alimento, montaria, companhia ou parte do ecossistema local. Exemplos: pequenos animais, aves comuns, criaturas domésticas.
C5: =COUNTIF(Plan1!J:J,D5) | D5: Comum | E5: Grau I — Comum Criaturas geralmente pacíficas que podem reagir quando ameaçadas ou protegendo filhotes. Possuem força suficiente para ferir uma pessoa despreparada, mas raramente representam perigo para aventureiros experientes. São abundantes e amplamente conhecidas. Exemplos: cervos, montarias comuns, grandes herbívoros.
C6: =COUNTIF(Plan1!J:J,D6) | D6: Menor | E6: Grau II — Menor Criaturas ariscas ou naturalmente agressivas. Possuem meios eficazes de defesa ou ataque e podem causar ferimentos sérios em indivíduos isolados. São consideradas perigosas para viajantes comuns. Exemplos: predadores pequenos e médios, criaturas venenosas, animais territoriais.
C7: =COUNTIF(Plan1!J:J,D7) | D7: Ameaça | E7: Grau III — Ameaça Criaturas capazes de matar um humanoide adulto com relativa facilidade. Possuem força, velocidade, venenos ou capacidades naturais suficientemente perigosas para exigir preparação. Embora letais, geralmente evitam confrontos desnecessários para conservar energia. Exemplos: grandes predadores, monstros de caça especializados.
C8: =COUNTIF(Plan1!J:J,D8) | D8: Elite | E8: Grau IV — Elite Predadores dominantes ou criaturas extremamente agressivas. Frequentemente atacam primeiro, defendem vastos territórios e representam ameaça significativa até para grupos organizados. Costumam ocupar o topo da cadeia alimentar regional. Exemplos: superpredadores, monstros territoriais excepcionais.
C9: =COUNTIF(Plan1!J:J,D9) | D9: Lendário | E9: Grau V — Lendário Criaturas cuja simples presença altera o equilíbrio de uma região. Possuem inteligência elevada, enorme poder físico ou capacidades sobrenaturais raras. São frequentemente tema de lendas, religiões e histórias locais. Enfrentá-las exige planejamento, recursos e experiência. Exemplos: dragões maiores, matriarcas monstruosas, guardiões ancestrais.
C10: =COUNTIF(Plan1!J:J,D10) | D10: Mítico | E10: Grau VI — Mítico Seres dotados de consciência avançada e compreensão do mundo. Frequentemente possuem cultura, linguagem, conhecimento ancestral ou poderes capazes de influenciar civilizações inteiras. Podem negociar, governar ou manipular eventos históricos. Exemplos: dragões extremamente antigos, entidades primordiais menores.
C11: =COUNTIF(Plan1!J:J,D11) | D11: Cataclísmico | E11: Grau VII — Cataclísmico Criaturas capazes de destruir cidades, reinos ou regiões inteiras. Sua existência representa uma ameaça estratégica para nações. O surgimento de uma criatura desse nível costuma mobilizar exércitos inteiros. Exemplos: Dragões Anciões, titãs primordiais, monstros do Negativo.
C12: =COUNTIF(Plan1!J:J,D12) | D12: Apocalíptico | E12: Grau VIII — Apocalíptico Entidades capazes de alterar o destino do mundo. Sua ação pode levar à extinção de espécies, destruição de continentes ou colapso de civilizações inteiras. São consideradas ameaças globais. Exemplos: entidades supremas do Negativo, Primordiais corrompidos, seres ligados ao fim dos tempos.
A15: =SUM(A16:A42) | B15: =SUM(B16:B42) | C15: =SUM(C16:C42) | D15: Categoria | E15: Descrição
A16: =B16-C16 | B16: 24 | C16: =COUNTIF(Plan1!G:G,D16) | D16: Besta Mágica | E16: São criaturas que possui ligação com um ou mais elementos (Terra, Fogo, Agua, Vento ou Trovão)
A17: =B17-C17 | B17: 6 | C17: =COUNTIF(Plan1!G:G,D17) | D17: Besta Mágica - Tribal | E17: São criaturas que tem conciencias e linguagem, possui elementos, mas algumas especies pode ter apenas famialidade com Arcano
A18: =B18-C18 | B18: 8 | C18: =COUNTIF(Plan1!G:G,D18) | D18: Besta Mágica Suprema | E18: São Criaturas que possui ligação com um ou mais elementos adicionalmente elementos de entidade Sagrado ou Caótico
A19: =B19-C19 | B19: 1 | C19: =COUNTIF(Plan1!G:G,D19) | D19: Dragão Superior | E19: Criaturas de origem comum de dragões mais de nivies mitologicos
A20: =B20-C20 | B20: 8 | C20: =COUNTIF(Plan1!G:G,D20) | D20: Aquático Mágico | E20: São criaturas de origem marinha que não consegue viver fora da agua e possui ligação com um ou mais elementos
A21: =B21-C21 | B21: 6 | C21: =COUNTIF(Plan1!G:G,D21) | D21: Aquático Mágico Supremo | E21: São criaturas de origem marinha que não consegue viver fora da agua e possui ligação com um ou mais elementos adicionalmente naturezas divinas com oSagrados ou Caótico
A22: =B22-C22 | B22: 10 | C22: =COUNTIF(Plan1!G:G,D22) | D22: Místicos Mágicos | E22: São criaturas, ligadas a magia de origem arcana pode ou não contem elementos que não existentes a esse plano
A23: =B23-C23 | B23: 8 | C23: =COUNTIF(Plan1!G:G,D23) | D23: Místicos Mágicos Supremo | E23: São criaturas, ligadas a magia geralmente arcana e sagrado ou caóticos não existentes a esse plano
A24: =B24-C24 | B24: 10 | C24: =COUNTIF(Plan1!G:G,D24) | D24: Anfíbio Mágico | E24: Criaturas que vivem nasceram na agua mas pode viver fora em terra, e possui ligação com elementos
A25: =B25-C25 | B25: 4 | C25: =COUNTIF(Plan1!G:G,D25) | D25: Anfíbio Mágico Supremo | E25: Criaturas que vivem nasceram na agua mas pode viver fora em terra, e possui ligação com elementos incluindo de entidades sagradas ou caóticas
A26: =B26-C26 | B26: 15 | C26: =COUNTIF(Plan1!G:G,D26) | D26: Criatura do Negativo | E26: Criaturas que foram corrompdas pelo Negativo e perderam totalmente suas propriedades
A27: =B27-C27 | B27: 8 | C27: =COUNTIF(Plan1!G:G,D27) | D27: Criatura do Negativo Supremo | E27: Criaturas que foram corrompdas pelo Negativo e perderam totalmente suas propriedades com ligação forte a entidade do Nada.
... A35: =B35-C35 | B35: 1 | C35: =COUNTIF(Plan1!G:G,D35) | D35: Dragão Primordial | E35: Criaturas de origem comum de dragões mais antigos

Sheet LEGADO
A1: Dados base | M1: Possiveis Itens | N1: Estatísticas | AA1: Habilidades | AF1: Perícias
A2: Nome | B2: Anotação | C2: Descricao | D2: Aparencia | E2: Habitat | F2: Curiosidades de Astrolong TerraNova | G2: Categoria | H2: Tipo | I2: Natureza | J2: Grau de Ameaça | K2: Tamanho | L2: Comportamento | M2: Itens | N2: FOR | O2: DES | P2: VIT | Q2: INT | R2: PRE | S2: Vida | T2: Defesa | U2: Mana | V2: Ataque Basico | W2: CD Conjurador | X2: Atributo Conjurador | Y2: Resistencia | Z2: Fraqueza | AA2: Habilidade 1 | AB2: Habilidade 2 | AC2: Habilidade 3 | AD2: Habilidade 4 | AE2: Habilidade 5 | AF2: Atletismo | AG2: Reflexo | AH2: Tenacidade | AI2: Vontade | AJ2: Foco | AK2: Luta | AL2: Sobrevivência
A3: Dríade das Florestas Ancestrais | B3: Poucos aventureiros encontram uma Dríade. Menos ainda percebem que foram observados por uma durante toda a viagem. — Astrolong TerraNova | C3: As Dríades das Florestas Ancestrais são criaturas humanoides compostas por madeira viva, folhas, flores e mana natural. Diferente do que muitos acreditam, elas não são espíritos nem elementais. São seres vivos pertencentes à categoria das Bestas Mágicas e possuem sociedades próprias escondidas nas profundezas das florestas élficas. Suas comunidades raramente ultrapassam algumas dezenas de indivíduos e costumam existir próximas a árvores ancestrais ou fontes naturais de mana. Embora possuam aparência delicada, as Dríades vivem por séculos e acumulam conhecimento profundo sobre a floresta. | D3: Criatura humanide que se assemelha muita a humanos e elfos, com corpos cobertos de vegetação, tem rosto simpaticos e muita belas. | E3: Reino dos Elfos, Florestas Ancestrais | F3: Muitos aventureiros descrevem as Dríades como belas. Isso é verdade. Porém, a beleza não é a característica mais impressionante delas. O que realmente chama atenção é sua capacidade de permanecer completamente imóvel por horas. Mais de uma vez passei por uma árvore para descobrir, dias depois, que ela estava me observando. | G3: Besta Mágica - Tribal | H3: Planta | I3: Arcano, Água e Terra | J3: Comum | K3: Médio | L3: Tribal, Social e Pacificos | M3: Flores de Mana Sementes Feéricas Essência Natural Frutos Ancestrais | N3: 1 | O3: 2 | P3: 2 | Q3: 2 | R3: 3 | S3: 24 | T3: 13 | U3: 6 | W3: 13 | X3: PRE | AA3: Toque Vital (custo 2 PM, 3x por cena) - cura 1d6 + Presença de Vida em uma criatura tocada, ou causa 1d6 de dano de Terra em um inimigo (CD 13, salv. Tenacidade para metade). | AB3: Emaranhar (custo 2 PM, 2x por cena) - raízes seguram um alvo a 6m (CD 13, salv. Atletismo ou fica Aprisionado por 1 rodada). | AF3: 0 | AG3: 0 | AH3: 0 | AI3: 3 | AJ3: 2 | AK3: 0 | AL3: 2
A4: Ent Jovem | B4: Quando uma floresta deseja se defender, ela cria espinhos. Quando deseja se lembrar, cria Ents. — Astrolong TerraNova | C4: Os Ents Jovens são árvores despertas pela mana das Florestas Ancestrais. Diferente das Dríades, que possuem comunidades e cultura própria, os Ents existem como guardiões vivos da natureza. Seu corpo é formado por madeira viva extremamente resistente, coberta por musgos, flores, cipós e pequenos animais que frequentemente utilizam sua estrutura como abrigo. Embora sejam chamados de jovens, muitos já possuem mais de cinquenta anos de idade. O termo é utilizado pelos Elfos para diferenciar indivíduos que ainda não atingiram o tamanho colossal dos Ents Ancestrais. São criaturas lentas e pacientes. Um Ent pode permanecer imóvel por semanas observando uma mesma região antes de agir. | D4: Um Ent Jovem possui entre 4 e 6 metros de altura. Seu tronco lembra o de uma árvore centenária, enquanto seus braços assumem a forma de galhos robustos capazes de esmagar pedras. Seu rosto surge naturalmente na madeira, formado por rachaduras e nós que lembram olhos, nariz e boca. Durante a primavera, alguns desenvolvem flores e folhas coloridas em seus ombros e braços. | E4: Reino dos Elfos, Florestas Ancestrais | F4: Muitos aventureiros acreditam que os Ents são lentos porque são árvores. Estão enganados. Eles são lentos porque já viram séculos passarem diante de seus olhos. Para uma criatura que mede o tempo em florestas e não em anos, nós somos os apressados. | G4: Besta Mágica | H4: Planta | I4: Terra | J4: Ameaça | K4: Grande | L4: Territórialista | M4: Madeira Ancestral Seiva Encantada Núcleo de Mana Natural Sementes Primordiais | N4: 4 | O4: 1 | P4: 4 | Q4: 1 | R4: 1 | S4: 57 | T4: 14 | U4: 2 | W4: 9 | X4: INT | AA4: Raízes Imobilizantes (custo 2 PM, 3x por cena) - prende um inimigo a até 9m em raízes vivas (CD 9, salv. Atletismo ou fica Aprisionado por 1 rodada). | AB4: Golpe de Tronco (custo 2 PM, 2x por cena) - golpe de galho que causa 2d6 de dano de Terra adicional (CD 9, salv. Reflexo para metade). | AF4: 6 | AG4: 0 | AH4: 6 | AI4: 0 | AJ4: 0 | AK4: 4 | AL4: 2
A5: Ave do Paraíso Ancestral | B5: Durante décadas acreditei que os bardos exageravam ao descrever estas aves. Descobri meu erro no momento em que vi um bando cruzar o céu ao amanhecer. Nenhuma tinta é capaz de reproduzir todas as cores que brilham em suas penas. | C5: A Ave do Paraíso Ancestral é considerada uma das criaturas mais belas de todo o Continente Ancestral. Seu canto harmonioso pode ser ouvido ao amanhecer e ao entardecer, sendo frequentemente associado a presságios de boa sorte por viajantes e habitantes das florestas. Apesar de ser conhecida como uma única espécie, estudiosos catalogaram mais de duzentas variedades diferentes espalhadas pelas florestas, pradarias e bosques do continente. Cada espécie apresenta combinações únicas de cores, padrões e formatos de penas. As Dríades acreditam que essas aves surgiram quando os primeiros ventos da criação atravessaram as florestas recém-nascidas, espalhando fragmentos de mana sobre as árvores ancestrais. São criaturas extremamente importantes para o equilíbrio natural, atuando na dispersão de sementes, pólen mágico e pequenas essências naturais entre diferentes regiões da floresta. | D5: A Ave do Paraíso Ancestral possui entre 20 e 40 centímetros de comprimento, com corpo leve e elegante adaptado ao voo ágil entre galhos e copas densas. Suas penas apresentam uma impressionante variedade de cores vibrantes, incluindo tons de azul, verde-esmeralda, dourado, violeta, vermelho-rubi e branco-perolado. Algumas espécies possuem caudas longas que podem atingir três vezes o comprimento do corpo. Quando expostas à luz do sol ou à mana ambiente, certas penas produzem reflexos iridescentes que mudam constantemente de cor, criando um espetáculo visual difícil de descrever. Os machos geralmente apresentam plumagens mais extravagantes, enquanto as fêmeas possuem padrões mais discretos, porém igualmente belos. Diversas espécies desenvolvem pequenas cristas, leques de penas ou caudas ornamentais utilizadas durante elaborados rituais de acasalamento que transformam clareiras inteiras em verdadeiros espetáculos naturais. | E5: Reino dos Elfos, Terras dos Faunos e Florestas Ancestrais | F5: A maioria dos aventureiros observa apenas a plumagem dessas aves. Eu prefiro observar os outros animais ao seu redor. Em mais de uma ocasião, encontrei predadores descansando próximos a um bando de Aves do Paraíso Ancestrais sem demonstrar qualquer intenção de caça. Não compreendo completamente o motivo, mas suspeito que a mana presente em suas penas produza uma sensação de tranquilidade nas criaturas ao redor. | G5: Besta Mágica | H5: Ave | I5: Vento | J5: Inofensivo | K5: Pequeno | L5: Pacífico e Sociável | M5: Pena Arcoiris | N5: 0 | O5: 2 | P5: 1 | Q5: 0 | R5: 1 | S5: 11 | T5: 12 | U5: 2 | W5: 9 | X5: PRE | AA5: Canto Encantador (custo 1 PM, 2x por cena) - canto que acalma; uma criatura a 6m faz salv. Vontade (CD 9) ou fica Fascinada (não pode atacar a ave) por 1 rodada. | AF5: 0 | AG5: 2 | AH5: 0 | AI5: 0 | AJ5: 0 | AK5: 0 | AL5: 1
